Workbook

Sheet Assumptions
A1: Azure Bay Residences (Synthetic) — 850-Unit Luxury Condo Demo Workbook
A3: Sheets included:
A4: • Units_Residents — unit roster, owners/tenants, parking/boat/storage assignments
A5: • Accounts_AR — monthly assessments, balances, delinquency bucketing (formula-based)
A6: • Work_Orders — recent and active maintenance tickets
A7: • Violations — recent and active compliance items
A8: • Notices — board/management communications
A9: • Amenities_Parking — parking inventory and assignments
A10: • Amenities_BoatSlips — marina slip inventory and assignments
A11: • Vendors — vendor directory
A12: • SMS_Test_Set — example owner/resident questions for SMS/voice demos
A15: Tip: Demo flows that land well: balance/last payment, parking/boat slip, open work orders, and violations.

Sheet README

Sheet Units_Residents
A1: Unit | B1: Floor | C1: Stack | D1: Unit Type | E1: SqFt | F1: Occupancy Type | G1: Owner Name | H1: Owner Phone | I1: Owner Email | J1: Tenant Name | K1: Lease Expiration | L1: Parking Primary | M1: Parking Secondary | N1: Boat Slip | O1: Storage Unit | P1: SMS Opt-In
A2: 101 | B2: 1 | C2: 1 | D2: 1BR | E2: 934 | F2: Owner | G2: Henry Delgado | H2: (305) 555-1001 | I2: henry.delgado+101@demo-hoa.example | L2: P5-120 | P2: Y
A3: 102 | B3: 1 | C3: 2 | D3: 1BR | E3: 966 | F3: Renter | G3: Evelyn Gutierrez | H3: (305) 555-1002 | I3: evelyn.gutierrez+102@demo-hoa.example | J3: Benjamin Perez | K3: 46234 | L3: P4-124 | O3: S-234 | P3: Y
A4: 103 | B4: 1 | C4: 3 | D4: 1BR | E4: 915 | F4: Renter | G4: Mason Hernandez | H4: (305) 555-1003 | I4: mason.hernandez+103@demo-hoa.example | J4: Madison Perez | K4: 46259 | L4: P3-007 | P4: Y
A5: 104 | B5: 1 | C5: 4 | D5: 1BR | E5: 876 | F5: Owner | G5: Charlotte Gutierrez | H5: (305) 555-1004 | I5: charlotte.gutierrez+104@demo-hoa.example | L5: P2-058 | O5: S-039 | P5: Y
A6: 105 | B6: 1 | C6: 5 | D6: 1BR | E6: 877 | F6: Renter | G6: Emily Rivera | H6: (305) 555-1005 | I6: emily.rivera+105@demo-hoa.example | J6: Henry Gonzalez | K6: 46186 | L6: P1-035 | O6: S-094 | P6: Y
A7: 106 | B7: 1 | C7: 6 | D7: 1BR | E7: 855 | F7: Owner | G7: Noah Rodriguez | H7: (305) 555-1006 | I7: noah.rodriguez+106@demo-hoa.example | L7: P1-033 | O7: S-046 | P7: Y
A8: 107 | B8: 1 | C8: 7 | D8: 2BR | E8: 1450 | F8: Renter | G8: Lucas Flores | H8: (305) 555-1007 | I8: lucas.flores+107@demo-hoa.example | J8: Mia Martinez | K8: 46228 | L8: P2-279 | N8: B-035 | P8: N
A9: 108 | B9: 1 | C9: 8 | D9: 2BR | E9: 1485 | F9: Owner | G9: Abigail Ramirez | H9: (305) 555-1008 | I9: abigail.ramirez+108@demo-hoa.example | L9: P3-148 | N9: B-027 | O9: S-175 | P9: Y
A10: 109 | B10: 1 | C10: 9 | D10: 2BR | E10: 1393 | F10: Owner | G10: Evelyn Gomez | H10: (305) 555-1009 | I10: evelyn.gomez+109@demo-hoa.example | L10: P1-126 | M10: P3-190 | P10: N
A11: 110 | B11: 1 | C11: 10 | D11: 2BR | E11: 1190 | F11: Owner | G11: Charlotte Gomez | H11: (305) 555-1010 | I11: charlotte.gomez+110@demo-hoa.example | L11: P4-172 | M11: P2-229 | O11: S-198 | P11: Y
A12: 111 | B12: 1 | C12: 11 | D12: 2BR | E12: 1233 | F12: Owner | G12: Logan Rivera | H12: (305) 555-1011 | I12: logan.rivera+111@demo-hoa.example | L12: P1-188 | O12: S-309 | P12: Y
A13: 112 | B13: 1 | C13: 12 | D13: 2BR | E13: 1503 | F13: Owner | G13: Madison Morales | H13: (305) 555-1012 | I13: madison.morales+112@demo-hoa.example | L13: P1-244 | M13: P5-088 | O13: S-187 | P13: N
A14: 113 | B14: 1 | C14: 13 | D14: 3BR | E14: 2177 | F14: Renter | G14: Logan Ortiz | H14: (305) 555-1013 | I14: logan.ortiz+113@demo-hoa.example | J14: Amelia Martinez | K14: 46505 | L14: P1-236 | M14: P2-091 | O14: S-137 | P14: N
A15: 114 | B15: 1 | C15: 14 | D15: 3BR | E15: 1777 | F15: Owner | G15: Charlotte Romero | H15: (305) 555-1014 | I15: charlotte.romero+114@demo-hoa.example | L15: P5-207 | M15: P3-279 | P15: Y
A16: 115 | B16: 1 | C16: 15 | D16: 3BR | E16: 2181 | F16: Renter | G16: Michael Reyes | H16: (305) 555-1015 | I16: michael.reyes+115@demo-hoa.example | J16: Noah Reyes | K16: 46400 | L16: P3-087 | M16: P4-018 | N16: B-030 | O16: S-001 | P16: Y
A17: 116 | B17: 1 | C17: 16 | D17: 3BR | E17: 2086 | F17: Renter | G17: James Morales | H17: (305) 555-1016 | I17: james.morales+116@demo-hoa.example | J17: Liam Romero | K17: 46294 | L17: P5-137 | O17: S-215 | P17: N
A18: 117 | B18: 1 | C18: 17 | D18: PH | E18: 3544 | F18: Owner | G18: Michael Alvarez | H18: (305) 555-1017 | I18: michael.alvarez+117@demo-hoa.example | L18: P2-234 | M18: P1-133 | P18: Y
A19: 201 | B19: 2 | C19: 1 | D19: 1BR | E19: 852 | F19: Owner | G19: Charlotte Ramos | H19: (305) 555-1018 | I19: charlotte.ramos+201@demo-hoa.example | L19: P4-120 | O19: S-009 | P19: Y
A20: 202 | B20: 2 | C20: 2 | D20: 1BR | E20: 914 | F20: Owner | G20: Evelyn Gomez | H20: (305) 555-1019 | I20: evelyn.gomez+202@demo-hoa.example | L20: P2-088 | O20: S-188 | P20: Y
A21: 203 | B21: 2 | C21: 3 | D21: 1BR | E21: 849 | F21: Owner | G21: Sebastian Chavez | H21: (305) 555-1020 | I21: sebastian.chavez+203@demo-hoa.example | L21: P5-210 | O21: S-270 | P21: Y
A22: 204 | B22: 2 | C22: 4 | D22: 1BR | E22: 874 | F22: Owner | G22: Sophia Navarro | H22: (305) 555-1021 | I22: sophia.navarro+204@demo-hoa.example | L22: P4-048 | O22: S-123 | P22: Y
A23: 205 | B23: 2 | C23: 5 | D23: 1BR | E23: 842 | F23: Owner | G23: Mason Vega | H23: (305) 555-1022 | I23: mason.vega+205@demo-hoa.example | L23: P3-024 | O23: S-216 | P23: Y
A24: 206 | B24: 2 | C24: 6 | D24: 1BR | E24: 864 | F24: Owner | G24: Isabella Delgado | H24: (305) 555-1023 | I24: isabella.delgado+206@demo-hoa.example | L24: P1-182 | O24: S-266 | P24: Y
A25: 207 | B25: 2 | C25: 7 | D25: 2BR | E25: 1473 | F25: Renter | G25: Logan Gonzalez | H25: (305) 555-1024 | I25: logan.gonzalez+207@demo-hoa.example | J25: Alexander Vega | K25: 46157 | L25: P1-012 | M25: P3-218 | P25: Y
A26: 208 | B26: 2 | C26: 8 | D26: 2BR | E26: 1474 | F26: Renter | G26: Emily Hernandez | H26: (305) 555-1025 | I26: emily.hernandez+208@demo-hoa.example | J26: Harper Morales | K26: 46441 | L26: P1-191 | M26: P5-198 | P26: Y
A27: 209 | B27: 2 | C27: 9 | D27: 2BR | E27: 1246 | F27: Renter | G27: Liam Ruiz | H27: (305) 555-1026 | I27: liam.ruiz+209@demo-hoa.example | J27: Mia Gutierrez | K27: 46194 | L27: P1-185 | M27: P2-245 | O27: S-150 | P27: Y
A28: 210 | B28: 2 | C28: 10 | D28: 2BR | E28: 1325 | F28: Owner | G28: Logan Torres | H28: (305) 555-1027 | I28: logan.torres+210@demo-hoa.example | L28: P1-010 | M28: P5-228 | O28: S-162 | P28: Y
A29: 211 | B29: 2 | C29: 11 | D29: 2BR | E29: 1483 | F29: Owner | G29: Michael Vega | H29: (305) 555-1028 | I29: michael.vega+211@demo-hoa.example | L29: P1-100 | P29: N
A30: 212 | B30: 2 | C30: 12 | D30: 2BR | E30: 1221 | F30: Renter | G30: Amelia Castillo | H30: (305) 555-1029 | I30: amelia.castillo+212@demo-hoa.example | J30: Isabella Suarez | K30: 46408 | L30: P4-043 | O30: S-253 | P30: Y
A31: 213 | B31: 2 | C31: 13 | D31: 3BR | E31: 1900 | F31: Owner | G31: Noah Mendoza | H31: (305) 555-1030 | I31: noah.mendoza+213@demo-hoa.example | L31: P4-060 | M31: P3-282 | P31: Y
A32: 214 | B32: 2 | C32: 14 | D32: 3BR | E32: 1970 | F32: Renter | G32: Jackson Gomez | H32: (305) 555-1031 | I32: jackson.gomez+214@demo-hoa.example | J32: Charlotte Gonzalez | K32: 46496 | L32: P2-015 | M32: P5-111 | O32: S-081 | P32: Y
A33: 215 | B33: 2 | C33: 15 | D33: 3BR | E33: 1794 | F33: Owner | G33: Charlotte Navarro | H33: (305) 555-1032 | I33: charlotte.navarro+215@demo-hoa.example | L33: P5-284 | O33: S-250 | P33: Y
A34: 216 | B34: 2 | C34: 16 | D34: 3BR | E34: 1970 | F34: Renter | G34: Elijah Gutierrez | H34: (305) 555-1033 | I34: elijah.gutierrez+216@demo-hoa.example | J34: Harper Ortiz | K34: 46260 | L34: P5-105 | M34: P2-005 | P34: N
A35: 217 | B35: 2 | C35: 17 | D35: PH | E35: 2899 | F35: Owner | G35: Elijah Vargas | H35: (305) 555-1034 | I35: elijah.vargas+217@demo-hoa.example | L35: P1-101 | M35: P1-022 | P35: N
A36: 301 | B36: 3 | C36: 1 | D36: 1BR | E36: 930 | F36: Renter | G36: James Martinez | H36: (305) 555-1035 | I36: james.martinez+301@demo-hoa.example | J36: Charlotte Martinez | K36: 46412 | L36: P5-135 | O36: S-017 | P36: Y
A37: 302 | B37: 3 | C37: 2 | D37: 1BR | E37: 949 | F37: Renter | G37: Mia Gonzalez | H37: (305) 555-1036 | I37: mia.gonzalez+302@demo-hoa.example | J37: Mia Diaz | K37: 46285 | L37: P4-081 | P37: Y
A38: 303 | B38: 3 | C38: 3 | D38: 1BR | E38: 974 | F38: Owner | G38: Liam Gonzalez | H38: (305) 555-1037 | I38: liam.gonzalez+303@demo-hoa.example | L38: P5-002 | P38: Y
A39: 304 | B39: 3 | C39: 4 | D39: 1BR | E39: 858 | F39: Owner | G39: Alexander Rivera | H39: (305) 555-1038 | I39: alexander.rivera+304@demo-hoa.example | L39: P3-284 | O39: S-142 | P39: Y
A40: 305 | B40: 3 | C40: 5 | D40: 1BR | E40: 896 | F40: Renter | G40: Logan Ortiz | H40: (305) 555-1039 | I40: logan.ortiz+305@demo-hoa.example | J40: Sofia Ramos | K40: 46260 | L40: P4-254 | P40: Y
...

Sheet Accounts_AR
A1: Unit | B1: Account Holder | C1: Monthly Assessment | D1: Annual Assessment | E1: Special Assessment Active | F1: Special Assessment Balance | G1: Current Balance | H1: Last Payment Date | I1: Last Payment Amount | J1: Payment Method | K1: Last Assessment Due Date | L1: Days Past Due | M1: Delinquency Bucket | N1: Late Fees | O1: Payment Plan | P1: Autopay
A2: 101 | B2: Henry Delgado | C2: 725 | D2: =C2*12 -> 8700 | E2: Y | F2: 7947.67 | G2: 0 | H2: 46058 | I2: 584.81 | J2: Wire | K2: 46054 | L2: =IF(G2<=0,0,MAX(0,Assumptions!$B$3-K2)) -> 0 | M2: =IF(G2<=0,"Current",IF(L2<=30,"30 days",IF(L2<=60,"60 days",IF(L2<=90,"90 days","90+ days")))) -> Current | N2: 0 | O2: N | P2: N
A3: 102 | B3: Evelyn Gutierrez | C3: 725 | D3: =C3*12 -> 8700 | E3: N | F3: 0 | G3: 0 | H3: 46051 | I3: 657.02 | J3: Online Portal | K3: 46054 | L3: =IF(G3<=0,0,MAX(0,Assumptions!$B$3-K3)) -> 0 | M3: =IF(G3<=0,"Current",IF(L3<=30,"30 days",IF(L3<=60,"60 days",IF(L3<=90,"90 days","90+ days")))) -> Current | N3: 0 | O3: N | P3: Y
A4: 103 | B4: Mason Hernandez | C4: 725 | D4: =C4*12 -> 8700 | E4: N | F4: 0 | G4: 2275.09 | H4: 45984 | I4: 659.05 | J4: ACH | K4: 45964 | L4: =IF(G4<=0,0,MAX(0,Assumptions!$B$3-K4)) -> 0 | M4: =IF(G4<=0,"Current",IF(L4<=30,"30 days",IF(L4<=60,"60 days",IF(L4<=90,"90 days","90+ days")))) -> 30 days | N4: 0 | O4: N | P4: N
A5: 104 | B5: Charlotte Gutierrez | C5: 725 | D5: =C5*12 -> 8700 | E5: N | F5: 0 | G5: 0 | H5: 46061 | I5: 696.78 | J5: Online Portal | K5: 46054 | L5: =IF(G5<=0,0,MAX(0,Assumptions!$B$3-K5)) -> 0 | M5: =IF(G5<=0,"Current",IF(L5<=30,"30 days",IF(L5<=60,"60 days",IF(L5<=90,"90 days","90+ days")))) -> Current | N5: 0 | O5: N | P5: N
A6: 105 | B6: Emily Rivera | C6: 725 | D6: =C6*12 -> 8700 | E6: N | F6: 0 | G6: 0 | H6: 46030 | I6: 594.46 | J6: Check | K6: 46054 | L6: =IF(G6<=0,0,MAX(0,Assumptions!$B$3-K6)) -> 0 | M6: =IF(G6<=0,"Current",IF(L6<=30,"30 days",IF(L6<=60,"60 days",IF(L6<=90,"90 days","90+ days")))) -> Current | N6: 0 | O6: N | P6: N
A7: 106 | B7: Noah Rodriguez | C7: 725 | D7: =C7*12 -> 8700 | E7: Y | F7: 803.35 | G7: 0 | H7: 46058 | I7: 599.1 | J7: ACH | K7: 46054 | L7: =IF(G7<=0,0,MAX(0,Assumptions!$B$3-K7)) -> 0 | M7: =IF(G7<=0,"Current",IF(L7<=30,"30 days",IF(L7<=60,"60 days",IF(L7<=90,"90 days","90+ days")))) -> Current | N7: 0 | O7: N | P7: Y
A8: 107 | B8: Lucas Flores | C8: 890 | D8: =C8*12 -> 10680 | E8: N | F8: 0 | G8: 0 | H8: 46048 | I8: 851.87 | J8: Check | K8: 46054 | L8: =IF(G8<=0,0,MAX(0,Assumptions!$B$3-K8)) -> 0 | M8: =IF(G8<=0,"Current",IF(L8<=30,"30 days",IF(L8<=60,"60 days",IF(L8<=90,"90 days","90+ days")))) -> Current | N8: 0 | O8: N | P8: N
A9: 108 | B9: Abigail Ramirez | C9: 890 | D9: =C9*12 -> 10680 | E9: N | F9: 0 | G9: 25 | H9: 46063 | I9: 991.72 | J9: Credit Card | K9: 46054 | L9: =IF(G9<=0,0,MAX(0,Assumptions!$B$3-K9)) -> 0 | M9: =IF(G9<=0,"Current",IF(L9<=30,"30 days",IF(L9<=60,"60 days",IF(L9<=90,"90 days","90+ days")))) -> 30 days | N9: 0 | O9: N | P9: N
A10: 109 | B10: Evelyn Gomez | C10: 890 | D10: =C10*12 -> 10680 | E10: N | F10: 0 | G10: 0 | H10: 46067 | I10: 777.89 | J10: Online Portal | K10: 46054 | L10: =IF(G10<=0,0,MAX(0,Assumptions!$B$3-K10)) -> 0 | M10: =IF(G10<=0,"Current",IF(L10<=30,"30 days",IF(L10<=60,"60 days",IF(L10<=90,"90 days","90+ days")))) -> Current | N10: 0 | O10: N | P10: N
A11: 110 | B11: Charlotte Gomez | C11: 890 | D11: =C11*12 -> 10680 | E11: N | F11: 0 | G11: 25 | H11: 46063 | I11: 824.18 | J11: ACH | K11: 46054 | L11: =IF(G11<=0,0,MAX(0,Assumptions!$B$3-K11)) -> 0 | M11: =IF(G11<=0,"Current",IF(L11<=30,"30 days",IF(L11<=60,"60 days",IF(L11<=90,"90 days","90+ days")))) -> 30 days | N11: 0 | O11: N | P11: Y
A12: 111 | B12: Logan Rivera | C12: 890 | D12: =C12*12 -> 10680 | E12: N | F12: 0 | G12: 0 | H12: 46031 | I12: 880.96 | J12: Credit Card | K12: 46054 | L12: =IF(G12<=0,0,MAX(0,Assumptions!$B$3-K12)) -> 0 | M12: =IF(G12<=0,"Current",IF(L12<=30,"30 days",IF(L12<=60,"60 days",IF(L12<=90,"90 days","90+ days")))) -> Current | N12: 0 | O12: N | P12: Y
A13: 112 | B13: Madison Morales | C13: 890 | D13: =C13*12 -> 10680 | E13: N | F13: 0 | G13: 1048.65 | H13: 45916 | I13: 474.33 | J13: Wire | K13: 46024 | L13: =IF(G13<=0,0,MAX(0,Assumptions!$B$3-K13)) -> 0 | M13: =IF(G13<=0,"Current",IF(L13<=30,"30 days",IF(L13<=60,"60 days",IF(L13<=90,"90 days","90+ days")))) -> 30 days | N13: 0 | O13: N | P13: N
... A851: 5017 | B851: Jackson Vargas | C851: 1653 | D851: =C851*12 -> 19836 | E851: N | F851: 0 | G851: 0 | H851: 46034 | I851: 1702.32 | J851: Wire | K851: 46054 | L851: =IF(G851<=0,0,MAX(0,Assumptions!$B$3-K851)) -> 0 | M851: =IF(G851<=0,"Current",IF(L851<=30,"30 days",IF(L851<=60,"60 days",IF(L851<=90,"90 days","90+ days")))) -> Current | N851: 0 | O851: N | P851: N

Sheet Amenities_Parking
A1: Space ID | B1: Level | C1: Type | D1: Assigned Unit | E1: Notes
A2: P1-001 | B2: P1 | C2: Assigned | D2: 3810
A3: P1-002 | B3: P1 | C3: Guest
A4: P1-003 | B4: P1 | C4: Assigned | D4: 1006
A5: P1-004 | B5: P1 | C5: Assigned | D5: 611
A6: P1-005 | B6: P1 | C6: Assigned | D6: 4802
A7: P1-006 | B7: P1 | C7: Assigned | D7: 3516
A8: P1-007 | B8: P1 | C8: Valet
A9: P1-008 | B9: P1 | C9: Assigned | D9: 4412
A10: P1-009 | B10: P1 | C10: Assigned | D10: 715
A11: P1-010 | B11: P1 | C11: Assigned | D11: 210
A12: P1-011 | B12: P1 | C12: Assigned | D12: 2610
A13: P1-012 | B13: P1 | C13: Assigned | D13: 207
A14: P1-013 | B14: P1 | C14: Assigned | D14: 2805
A15: P1-014 | B15: P1 | C15: Valet
A16: P1-015 | B16: P1 | C16: Assigned | D16: 5012
A17: P1-016 | B17: P1 | C17: Assigned | D17: 311
A18: P1-017 | B18: P1 | C18: Assigned | D18: 4509
A19: P1-018 | B19: P1 | C19: Assigned | D19: 2517
A20: P1-019 | B20: P1 | C20: Assigned | D20: 1710
A21: P1-020 | B21: P1 | C21: Assigned | D21: 4604
A22: P1-021 | B22: P1 | C22: Assigned | D22: 3212
A23: P1-022 | B23: P1 | C23: Assigned | D23: 217
A24: P1-023 | B24: P1 | C24: Assigned | D24: 1307
A25: P1-024 | B25: P1 | C25: Guest
A26: P1-025 | B26: P1 | C26: Assigned | D26: 4207
A27: P1-026 | B27: P1 | C27: Assigned | D27: 3615
A28: P1-027 | B28: P1 | C28: Assigned | D28: 2903
A29: P1-028 | B29: P1 | C29: Assigned | D29: 3108
A30: P1-029 | B30: P1 | C30: Assigned | D30: 4110
A31: P1-030 | B31: P1 | C31: Assigned | D31: 3117
A32: P1-031 | B32: P1 | C32: Assigned | D32: 4812
A33: P1-032 | B33: P1 | C33: Assigned | D33: 3001
A34: P1-033 | B34: P1 | C34: Assigned | D34: 106
A35: P1-034 | B35: P1 | C35: Assigned | D35: 713
A36: P1-035 | B36: P1 | C36: Assigned | D36: 105
A37: P1-036 | B37: P1 | C37: Assigned | D37: 1413
... A40: P1-039 | B40: P1 | C40: Assigned | D40: 1211
A41: P1-040 | B41: P1 | C41: Valet
A42: P1-041 | B42: P1 | C42: Assigned | D42: 917
...

Sheet Amenities_BoatSlips
A1: Slip ID | B1: Assigned Unit | C1: Max Length | D1: Monthly Fee | E1: Waitlist
A2: B-001 | B2: 812 | C2: 45 | D2: 707.31 | E2: N
A3: B-002 | B3: 2617 | C3: 45 | D3: 514.02 | E3: N
A4: B-003 | B4: 1102 | C4: 32 | D4: 808.83 | E4: N
A5: B-004 | B5: 2010 | C5: 45 | D5: 845.25 | E5: N
A6: B-005 | B6: 2213 | C6: 32 | D6: 543.76 | E6: N
A7: B-006 | B7: 2908 | C7: 28 | D7: 624.77 | E7: N
A8: B-007 | B8: 4302 | C8: 50 | D8: 937.44 | E8: N
A9: B-008 | B9: 813 | C9: 45 | D9: 769.1 | E9: N
A10: B-009 | B10: 4109 | C10: 50 | D10: 601.28 | E10: N
A11: B-010 | B11: 2305 | C11: 30 | D11: 481.45 | E11: N
A12: B-011 | B12: 3615 | C12: 28 | D12: 434.99 | E12: N
A13: B-012 | B13: 2603 | C13: 40 | D13: 539.03 | E13: N
... A21: B-020 | B21: 3709 | C21: 40 | D21: 691.01 | E21: N
A22: B-021 | C22: 28 | D22: 627.94 | E22: N
A23: B-022 | B23: 3207 | C23: 35 | D23: 677.37 | E23: N
A24: B-023 | B24: 413 | C24: 28 | D24: 690.95 | E24: N
A25: B-024 | B25: 2709 | C25: 30 | D25: 764.79 | E25: N
A26: B-025 | B26: 3301 | C26: 32 | D26: 635.04 | E26: N
A27: B-026 | B27: 2017 | C27: 32 | D27: 530.66 | E27: N
A28: B-027 | B28: 108 | C28: 32 | D28: 673.97 | E28: N
A29: B-028 | B29: 2816 | C29: 32 | D29: 636.82 | E29: N
A30: B-029 | B30: 406 | C30: 35 | D30: 504.51 | E30: N
A31: B-030 | B31: 115 | C31: 40 | D31: 918.52 | E31: N
A32: B-031 | B32: 1801 | C32: 32 | D32: 474.66 | E32: N
A33: B-032 | B33: 2509 | C33: 28 | D33: 617.69 | E33: N
A34: B-033 | B34: 3713 | C34: 50 | D34: 957.07 | E34: N
... A57: B-056 | B57: 2308 | C57: 30 | D57: 545.42 | E57: N
A58: B-057 | C58: 32 | D58: 740.67 | E58: Y
A59: B-058 | B59: 2510 | C59: 40 | D59: 877.46 | E59: N
A60: B-059 | B60: 911 | C60: 40 | D60: 567.51 | E60: N
A61: B-060 | B61: 2901 | C61: 40 | D61: 917.36 | E61: N
A62: B-061 | B62: 1817 | C62: 32 | D62: 605.49 | E62: N
A63: B-062 | B63: 816 | C63: 35 | D63: 775.27 | E63: N
A64: B-063 | B64: 2604 | C64: 35 | D64: 781.13 | E64: N
A65: B-064 | B65: 1610 | C65: 35 | D65: 534.96 | E65: N
A66: B-065 | B66: 1906 | C66: 50 | D66: 737.71 | E66: N
A67: B-066 | B67: 3213 | C67: 30 | D67: 838.4 | E67: N
A68: B-067 | C68: 40 | D68: 629 | E68: N
A69: B-068 | C69: 40 | D69: 856.11 | E69: N
...

Sheet Vendors
A1: Vendor | B1: Category | C1: Primary Contact | D1: Phone | E1: Email | F1: Notes
A2: Seaside Group | B2: Pool | C2: James Perez | D2: (305) 555-3001 | E2: dispatch01@vendors.demo-hoa.example | F2: Preferred vendor
A3: BlueWave Maintenance | B3: Landscaping | C3: Sebastian Martinez | D3: (305) 555-3002 | E3: dispatch02@vendors.demo-hoa.example | F3: 24/7 on-call
A4: Biscayne Services | B4: Security | C4: Mason Ramirez | D4: (305) 555-3003 | E4: dispatch03@vendors.demo-hoa.example | F4: Requires escort
A5: BlueWave Services | B5: General Contractor | C5: Jackson Delgado | D5: (305) 555-3004 | E5: dispatch04@vendors.demo-hoa.example | F5: After-hours surcharge applies
A6: Seaside Services | B6: Fire/Life Safety | C6: Noah Gomez | D6: (305) 555-3005 | E6: dispatch05@vendors.demo-hoa.example | F6: Preferred vendor
A7: Biscayne Group | B7: General Contractor | C7: Grace Cruz | D7: (305) 555-3006 | E7: dispatch06@vendors.demo-hoa.example | F7: 24/7 on-call
A8: Atlantic Systems | B8: General Contractor | C8: Ethan Suarez | D8: (305) 555-3007 | E8: dispatch07@vendors.demo-hoa.example
A9: SunCoast Group | B9: Cleaning | C9: Daniel Rodriguez | D9: (305) 555-3008 | E9: dispatch08@vendors.demo-hoa.example | F9: 24/7 on-call
A10: Seaside Systems | B10: Fire/Life Safety | C10: Amelia Castillo | D10: (305) 555-3009 | E10: dispatch09@vendors.demo-hoa.example
A11: SunCoast Systems | B11: HVAC | C11: Alexander Ruiz | D11: (305) 555-3010 | E11: dispatch10@vendors.demo-hoa.example | F11: Preferred vendor
A12: Atlantic Maintenance | B12: Landscaping | C12: Elijah Hernandez | D12: (305) 555-3011 | E12: dispatch11@vendors.demo-hoa.example | F12: Preferred vendor
A13: BlueWave Maintenance | B13: Fire/Life Safety | C13: Noah Vargas | D13: (305) 555-3012 | E13: dispatch12@vendors.demo-hoa.example | F13: 24/7 on-call
A14: Biscayne Contracting | B14: HVAC | C14: Emily Gonzalez | D14: (305) 555-3013 | E14: dispatch13@vendors.demo-hoa.example
A15: Biscayne Services | B15: Elevator | C15: Ethan Lopez | D15: (305) 555-3014 | E15: dispatch14@vendors.demo-hoa.example
A16: BlueWave Contracting | B16: Landscaping | C16: Harper Suarez | D16: (305) 555-3015 | E16: dispatch15@vendors.demo-hoa.example
A17: Biscayne Services | B17: Plumbing | C17: Alexander Suarez | D17: (305) 555-3016 | E17: dispatch16@vendors.demo-hoa.example
A18: BlueWave Services | B18: Plumbing | C18: Mia Diaz | D18: (305) 555-3017 | E18: dispatch17@vendors.demo-hoa.example | F18: Requires escort
A19: Atlantic Systems | B19: Electrical | C19: Liam Lopez | D19: (305) 555-3018 | E19: dispatch18@vendors.demo-hoa.example | F19: After-hours surcharge applies
A20: BlueWave Services | B20: Fire/Life Safety | C20: Sophia Romero | D20: (305) 555-3019 | E20: dispatch19@vendors.demo-hoa.example | F20: COI on file
A21: BlueWave Group | B21: Pool | C21: Madison Morales | D21: (305) 555-3020 | E21: dispatch20@vendors.demo-hoa.example | F21: Preferred vendor
A22: Biscayne Maintenance | B22: Elevator | C22: Liam Flores | D22: (305) 555-3021 | E22: dispatch21@vendors.demo-hoa.example | F22: After-hours surcharge applies
A23: Biscayne Contracting | B23: Landscaping | C23: Olivia Sanchez | D23: (305) 555-3022 | E23: dispatch22@vendors.demo-hoa.example | F23: After-hours surcharge applies
A24: Atlantic Group | B24: Electrical | C24: Harper Castillo | D24: (305) 555-3023 | E24: dispatch23@vendors.demo-hoa.example
A25: Coral Solutions | B25: Pool | C25: Mia Gonzalez | D25: (305) 555-3024 | E25: dispatch24@vendors.demo-hoa.example | F25: COI on file
A26: Biscayne Services | B26: Plumbing | C26: Mason Rodriguez | D26: (305) 555-3025 | E26: dispatch25@vendors.demo-hoa.example | F26: After-hours surcharge applies
A27: BlueWave Contracting | B27: Pool | C27: Sophia Cruz | D27: (305) 555-3026 | E27: dispatch26@vendors.demo-hoa.example | F27: COI on file
A28: Coral Services | B28: General Contractor | C28: Daniel Rivera | D28: (305) 555-3027 | E28: dispatch27@vendors.demo-hoa.example | F28: Preferred vendor
A29: Biscayne Maintenance | B29: Security | C29: Charlotte Gonzalez | D29: (305) 555-3028 | E29: dispatch28@vendors.demo-hoa.example | F29: 24/7 on-call
A30: Coral Maintenance | B30: Elevator | C30: Sofia Navarro | D30: (305) 555-3029 | E30: dispatch29@vendors.demo-hoa.example | F30: COI on file
A31: Seaside Group | B31: Landscaping | C31: Ella Delgado | D31: (305) 555-3030 | E31: dispatch30@vendors.demo-hoa.example | F31: 24/7 on-call

Sheet Work_Orders
A1: Work Order ID | B1: Opened | C1: Unit | D1: Category | E1: Priority | F1: Status | G1: Vendor | H1: Description | I1: ETA
A2: WO-20260001 | B2: 45972 | D2: Common Area | E2: High | F2: Open | G2: Biscayne Contracting | H2: Pool pump noise | I2: 45978
A3: WO-20260002 | B3: 45976 | D3: Common Area | E3: Low | F3: Open | G3: BlueWave Contracting | H3: Lobby HVAC warm | I3: 45982
A4: WO-20260003 | B4: 46040 | C4: 2211 | D4: Plumbing | E4: Medium | F4: In Progress | G4: Biscayne Contracting | H4: Toilet running continuously | I4: 46046
A5: WO-20260004 | B5: 46048 | D5: Common Area | E5: Low | F5: Awaiting Vendor | G5: Seaside Services | H5: Lobby HVAC warm | I5: 46054
A6: WO-20260005 | B6: 46014 | D6: Common Area | E6: Low | F6: Open | G6: SunCoast Group | H6: Hallway lighting outage | I6: 46024
A7: WO-20260006 | B7: 46068 | C7: 3806 | D7: Plumbing | E7: Low | F7: Awaiting Vendor | G7: Biscayne Services | H7: Shower drain slow | I7: 46083
A8: WO-20260007 | B8: 45965 | D8: Elevator | E8: Low | F8: Closed | G8: BlueWave Services | H8: Elevator #2 slow leveling
A9: WO-20260008 | B9: 46032 | C9: 1010 | D9: HVAC | E9: High | F9: Awaiting Vendor | G9: Biscayne Maintenance | H9: AC not cooling below 76°F | I9: 46041
A10: WO-20260009 | B10: 45986 | D10: Common Area | E10: Low | F10: Open | G10: BlueWave Group | H10: Pool pump noise | I10: 46000
A11: WO-20260010 | B11: 46012 | C11: 2804 | D11: Elevator | E11: Low | F11: Closed | G11: SunCoast Systems | H11: Elevator #2 slow leveling
A12: WO-20260011 | B12: 46028 | C12: 4114 | D12: Electrical | E12: High | F12: In Progress | G12: SunCoast Systems | H12: GFCI reset needed | I12: 46035
A13: WO-20260012 | B13: 46044 | C13: 707 | D13: HVAC | E13: Low | F13: Closed | G13: BlueWave Contracting | H13: Filter replacement request
A14: WO-20260013 | B14: 46075 | C14: 3408 | D14: Plumbing | E14: Low | F14: Open | G14: BlueWave Contracting | H14: Intermittent leak under sink | I14: 46078
A15: WO-20260014 | B15: 46049 | C15: 4507 | D15: Plumbing | E15: High | F15: Awaiting Vendor | G15: BlueWave Services | H15: Shower drain slow | I15: 46063
A16: WO-20260015 | B16: 46040 | D16: Common Area | E16: Low | F16: In Progress | G16: Atlantic Systems | H16: Lobby HVAC warm | I16: 46058
A17: WO-20260016 | B17: 46063 | D17: Common Area | E17: Medium | F17: Open | G17: Seaside Group | H17: Lobby HVAC warm | I17: 46075
A18: WO-20260017 | B18: 45985 | C18: 602 | D18: Plumbing | E18: Low | F18: Open | G18: BlueWave Contracting | H18: Intermittent leak under sink | I18: 45994
A19: WO-20260018 | B19: 46069 | C19: 1414 | D19: Electrical | E19: Low | F19: Closed | G19: Coral Services | H19: Outlet not working
A20: WO-20260019 | B20: 46029 | C20: 3011 | D20: Common Area | E20: Low | F20: Closed | G20: Biscayne Group | H20: Lobby HVAC warm
A21: WO-20260020 | B21: 45985 | C21: 201 | D21: Plumbing | E21: Medium | F21: Open | G21: Atlantic Systems | H21: Toilet running continuously | I21: 46001
A22: WO-20260021 | B22: 46021 | D22: Common Area | E22: Medium | F22: Open | G22: Atlantic Systems | H22: Lobby HVAC warm | I22: 46033
A23: WO-20260022 | B23: 46050 | C23: 4714 | D23: Common Area | E23: Low | F23: In Progress | G23: Coral Services | H23: Hallway lighting outage | I23: 46060
A24: WO-20260023 | B24: 45968 | C24: 2413 | D24: Electrical | E24: Medium | F24: Open | G24: BlueWave Maintenance | H24: Breaker tripping in kitchen | I24: 45986
A25: WO-20260024 | B25: 46045 | D25: Common Area | E25: Medium | F25: Open | G25: Seaside Systems | H25: Hallway lighting outage | I25: 46060
A26: WO-20260025 | B26: 46021 | C26: 2016 | D26: Plumbing | E26: Medium | F26: Open | G26: Biscayne Services | H26: Intermittent leak under sink | I26: 46024
A27: WO-20260026 | B27: 46018 | D27: Elevator | E27: Low | F27: In Progress | G27: Seaside Group | H27: Door sensor issue | I27: 46038
A28: WO-20260027 | B28: 46045 | C28: 3405 | D28: Electrical | E28: Low | F28: Awaiting Vendor | G28: Biscayne Services | H28: Outlet not working | I28: 46065
A29: WO-20260028 | B29: 46075 | C29: 4104 | D29: HVAC | E29: Urgent | F29: Open | G29: BlueWave Contracting | H29: Condensation near air handler | I29: 46078
A30: WO-20260029 | B30: 46043 | D30: Elevator | E30: High | F30: In Progress | G30: Coral Services | H30: Service mode active unexpectedly | I30: 46057
A31: WO-20260030 | B31: 45975 | C31: 3909 | D31: Elevator | E31: Low | F31: Open | G31: BlueWave Contracting | H31: Service mode active unexpectedly | I31: 45980
A32: WO-20260031 | B32: 45971 | C32: 3706 | D32: HVAC | E32: Medium | F32: In Progress | G32: Biscayne Services | H32: Filter replacement request | I32: 45976
A33: WO-20260032 | B33: 46056 | C33: 1805 | D33: Plumbing | E33: Urgent | F33: In Progress | G33: BlueWave Services | H33: Toilet running continuously | I33: 46065
A34: WO-20260033 | B34: 46046 | C34: 2706 | D34: Common Area | E34: Low | F34: Awaiting Vendor | G34: BlueWave Services | H34: Pool pump noise | I34: 46066
A35: WO-20260034 | B35: 46003 | C35: 2715 | D35: Common Area | E35: High | F35: Open | G35: Coral Services | H35: Pool pump noise | I35: 46010
A36: WO-20260035 | B36: 45962 | C36: 4014 | D36: Electrical | E36: Low | F36: Open | G36: BlueWave Maintenance | H36: GFCI reset needed | I36: 45981
A37: WO-20260036 | B37: 45967 | C37: 607 | D37: Plumbing | E37: Medium | F37: Closed | G37: Biscayne Contracting | H37: Intermittent leak under sink
A38: WO-20260037 | B38: 45995 | D38: Common Area | E38: Low | F38: Closed | G38: Seaside Group | H38: Lobby HVAC warm
A39: WO-20260038 | B39: 46045 | C39: 4305 | D39: HVAC | E39: High | F39: Awaiting Vendor | G39: BlueWave Group | H39: Filter replacement request | I39: 46051
A40: WO-20260039 | B40: 45961 | C40: 2714 | D40: Plumbing | E40: Urgent | F40: Awaiting Vendor | G40: Atlantic Systems | H40: Toilet running continuously | I40: 45979
...

Sheet Violations
A1: Violation ID | B1: Notice Date | C1: Unit | D1: Type | E1: Status | F1: Cure Deadline | G1: Fine | H1: Hearing Required | I1: Notes
A2: VIOL-20260001 | B2: 46075 | C2: 2305 | D2: Short-term rental | E2: Open | F2: 46089 | G2: 250 | H2: N | I2: Resident contacted by phone
A3: VIOL-20260002 | B3: 45978 | C3: 2707 | D3: Short-term rental | E3: Open | F3: 45985 | G3: 50 | H3: N | I3: Board review required
A4: VIOL-20260003 | B4: 45904 | C4: 2409 | D4: Balcony | E4: Open | F4: 45911 | G4: 250 | H4: N | I4: Board review required
A5: VIOL-20260004 | B5: 45981 | C5: 1901 | D5: Short-term rental | E5: Hearing Scheduled | F5: 45991 | G5: 25 | H5: Y | I5: Board review required
A6: VIOL-20260005 | B6: 45937 | C6: 2009 | D6: Parking | E6: Fine Assessed | F6: 45951 | G6: 100 | H6: Y | I6: Resident contacted by phone
A7: VIOL-20260006 | B7: 45918 | C7: 116 | D7: Balcony | E7: Fine Assessed | F7: 45928 | G7: 50 | H7: Y | I7: Second notice sent
A8: VIOL-20260007 | B8: 46000 | C8: 3407 | D8: Parking | E8: Cured | F8: 46021 | G8: 0 | H8: N | I8: Board review required
A9: VIOL-20260008 | B9: 45920 | C9: 2812 | D9: Noise | E9: Cured | F9: 45941 | G9: 100 | H9: N | I9: Resident contacted by phone
A10: VIOL-20260009 | B10: 45942 | C10: 3905 | D10: Pet | E10: Cured | F10: 45963 | G10: 100 | H10: N | I10: Photo on file in portal
A11: VIOL-20260010 | B11: 45982 | C11: 215 | D11: Balcony | E11: Fine Assessed | F11: 45992 | G11: 25 | H11: Y | I11: Photo on file in portal
A12: VIOL-20260011 | B12: 45930 | C12: 2807 | D12: Short-term rental | E12: Open | F12: 45940 | G12: 0 | H12: N | I12: Photo on file in portal
A13: VIOL-20260012 | B13: 46053 | C13: 817 | D13: Balcony | E13: Hearing Scheduled | F13: 46067 | G13: 50 | H13: N
A14: VIOL-20260013 | B14: 45942 | C14: 3514 | D14: Pet | E14: Closed | F14: 45963 | G14: 0 | H14: N | I14: Courtesy warning
A15: VIOL-20260014 | B15: 46055 | C15: 3406 | D15: Short-term rental | E15: Hearing Scheduled | F15: 46069 | G15: 0 | H15: N | I15: Board review required
A16: VIOL-20260015 | B16: 45983 | C16: 2104 | D16: Pet | E16: Closed | F16: 45990 | G16: 50 | H16: N | I16: Board review required
A17: VIOL-20260016 | B17: 45959 | C17: 1809 | D17: Noise | E17: Fine Assessed | F17: 45969 | G17: 50 | H17: Y | I17: Resident contacted by phone
A18: VIOL-20260017 | B18: 46028 | C18: 4804 | D18: Parking | E18: Cured | F18: 46038 | G18: 25 | H18: N | I18: Photo on file in portal
A19: VIOL-20260018 | B19: 45920 | C19: 4316 | D19: Pet | E19: Closed | F19: 45941 | G19: 25 | H19: N | I19: Second notice sent
A20: VIOL-20260019 | B20: 46034 | C20: 909 | D20: Pet | E20: Cured | F20: 46041 | G20: 50 | H20: N | I20: Photo on file in portal
A21: VIOL-20260020 | B21: 46008 | C21: 4408 | D21: Noise | E21: Open | F21: 46018 | G21: 0 | H21: N | I21: Resident contacted by phone
A22: VIOL-20260021 | B22: 45987 | C22: 4201 | D22: Balcony | E22: Cured | F22: 45994 | G22: 25 | H22: N | I22: Board review required
A23: VIOL-20260022 | B23: 45946 | C23: 811 | D23: Parking | E23: Fine Assessed | F23: 45956 | G23: 25 | H23: Y | I23: Photo on file in portal
A24: VIOL-20260023 | B24: 45928 | C24: 202 | D24: Architectural | E24: Open | F24: 45949 | G24: 0 | H24: N
A25: VIOL-20260024 | B25: 45988 | C25: 2512 | D25: Parking | E25: Open | F25: 45998 | G25: 0 | H25: N | I25: Second notice sent
A26: VIOL-20260025 | B26: 46004 | C26: 2906 | D26: Architectural | E26: Cured | F26: 46018 | G26: 250 | H26: N | I26: Courtesy warning
A27: VIOL-20260026 | B27: 46074 | C27: 409 | D27: Parking | E27: Cured | F27: 46084 | G27: 0 | H27: N
A28: VIOL-20260027 | B28: 46008 | C28: 4404 | D28: Balcony | E28: Open | F28: 46029 | G28: 0 | H28: N | I28: Board review required
A29: VIOL-20260028 | B29: 45937 | C29: 4815 | D29: Noise | E29: Open | F29: 45944 | G29: 0 | H29: N | I29: Courtesy warning
A30: VIOL-20260029 | B30: 45932 | C30: 3911 | D30: Noise | E30: Closed | F30: 45939 | G30: 0 | H30: N | I30: Resident contacted by phone
A31: VIOL-20260030 | B31: 45980 | C31: 102 | D31: Pet | E31: Closed | F31: 45987 | G31: 250 | H31: N | I31: Photo on file in portal
A32: VIOL-20260031 | B32: 45995 | C32: 1204 | D32: Balcony | E32: Hearing Scheduled | F32: 46002 | G32: 250 | H32: Y | I32: Board review required
A33: VIOL-20260032 | B33: 46062 | C33: 5008 | D33: Pet | E33: Open | F33: 46069 | G33: 50 | H33: N | I33: Photo on file in portal
A34: VIOL-20260033 | B34: 45965 | C34: 3613 | D34: Balcony | E34: Open | F34: 45986 | G34: 25 | H34: N
A35: VIOL-20260034 | B35: 45908 | C35: 604 | D35: Short-term rental | E35: Fine Assessed | F35: 45922 | G35: 100 | H35: N
A36: VIOL-20260035 | B36: 46000 | C36: 1412 | D36: Short-term rental | E36: Open | F36: 46021 | G36: 50 | H36: N | I36: Resident contacted by phone
A37: VIOL-20260036 | B37: 45933 | C37: 3509 | D37: Parking | E37: Closed | F37: 45947 | G37: 0 | H37: N | I37: Resident contacted by phone
A38: VIOL-20260037 | B38: 46010 | C38: 1714 | D38: Architectural | E38: Hearing Scheduled | F38: 46031 | G38: 250 | H38: Y | I38: Resident contacted by phone
A39: VIOL-20260038 | B39: 45944 | C39: 909 | D39: Architectural | E39: Open | F39: 45958 | G39: 100 | H39: N | I39: Photo on file in portal
A40: VIOL-20260039 | B40: 46021 | C40: 4708 | D40: Noise | E40: Open | F40: 46035 | G40: 25 | H40: N | I40: Photo on file in portal
...

Sheet Notices
A1: Notice ID | B1: Sent Date | C1: Category | D1: Title | E1: Delivery | F1: Summary
A2: NTC-2026001 | B2: 46012 | C2: Safety | D2: Fire Alarm Testing — Tower A | E2: SMS | F2: Work will occur overnight to minimize disruption. Expect brief elevator downtime per bank.
A3: NTC-2026002 | B3: 45987 | C3: Amenities | D3: Valet Service Hours Update | E3: Portal | F3: New RFID readers will be installed. Existing fobs will continue to work after migration.
A4: NTC-2026003 | B4: 45963 | C4: Finance | D4: Annual Budget Meeting Notice | E4: SMS | F4: Water will be off 9am–1pm. Please plan accordingly and report any leaks after restore.
A5: NTC-2026004 | B5: 46016 | C5: Safety | D5: Water Shutoff Notice (Floors 12–18) | E5: SMS | F5: Special assessment remains in effect. Online portal supports one-time or scheduled payments.
A6: NTC-2026005 | B6: 46020 | C6: Governance | D6: Board Meeting Agenda & Dial-in Details | E6: Email+SMS | F6: Agenda includes vendor contract renewals, reserve study update, and rule enforcement.
A7: NTC-2026006 | B7: 46051 | C7: Safety | D7: Fire Alarm Testing — Tower A | E7: Portal | F7: Work will occur overnight to minimize disruption. Expect brief elevator downtime per bank.
A8: NTC-2026007 | B8: 46061 | C8: Hurricane Prep | D8: Hurricane Season Preparation Checklist | E8: Email | F8: Work will occur overnight to minimize disruption. Expect brief elevator downtime per bank.
A9: NTC-2026008 | B9: 45957 | C9: Operations | D9: Garage Gate Access System Upgrade | E9: SMS | F9: Water will be off 9am–1pm. Please plan accordingly and report any leaks after restore.
A10: NTC-2026009 | B10: 45956 | C10: Amenities | D10: Valet Service Hours Update | E10: Email | F10: Work will occur overnight to minimize disruption. Expect brief elevator downtime per bank.
A11: NTC-2026010 | B11: 45957 | C11: Operations | D11: Garage Gate Access System Upgrade | E11: Email+SMS | F11: Updated hours effective next week. After-hours service available by request.
A12: NTC-2026011 | B12: 45991 | C12: Operations | D12: Elevator Preventive Maintenance Schedule | E12: Email | F12: Work will occur overnight to minimize disruption. Expect brief elevator downtime per bank.
A13: NTC-2026012 | B13: 45958 | C13: Finance | D13: Annual Budget Meeting Notice | E13: Portal | F13: Budget packet available in the portal. Owners may attend in person or via conference line.
... A21: NTC-2026020 | B21: 45985 | C21: Finance | D21: Annual Budget Meeting Notice | E21: Portal | F21: Budget packet available in the portal. Owners may attend in person or via conference line.

Sheet SMS_Test_Set
A1: Scenario ID | B1: Channel | C1: From | D1: Unit | E1: Message | F1: Expected Data | G1: Notes
A2: SCN-001 | B2: SMS | C2: (305) 555-6001 | D2: 3806 | E2: What is my current balance? | F2: Current Balance | G2: Balance inquiry
A3: SCN-002 | B3: SMS | C3: (305) 555-6002 | D3: 3415 | E3: What is my current balance? | F3: Current Balance | G3: Balance inquiry
A4: SCN-003 | B4: Voice | C4: (305) 555-6003 | D4: 4105 | E4: Am I enrolled in autopay? | F4: Autopay | G4: Autopay
A5: SCN-004 | B5: SMS | C5: (305) 555-6004 | D5: 3304 | E5: Is my work order still open? | F5: Work Orders | G5: Work order status
A6: SCN-005 | B6: SMS | C6: (305) 555-6005 | D6: 1416 | E6: When does my tenant lease expire? | F6: Lease Expiration | G6: Lease
A7: SCN-006 | B7: Voice | C7: (305) 555-6006 | D7: 3513 | E7: Do I have a special assessment? | F7: Special Assessment Active | G7: Special assessment
A8: SCN-007 | B8: SMS | C8: (305) 555-6007 | D8: 2612 | E8: Is my work order still open? | F8: Work Orders | G8: Work order status
A9: SCN-008 | B9: SMS | C9: (305) 555-6008 | D9: 1804 | E9: Do I have a boat slip assigned? | F9: Boat Slip | G9: Boat slip
A10: SCN-009 | B10: SMS | C10: (305) 555-6009 | D10: 508 | E10: Do I have a boat slip assigned? | F10: Boat Slip | G10: Boat slip
A11: SCN-010 | B11: SMS | C11: (305) 555-6010 | D11: 3217 | E11: When does my tenant lease expire? | F11: Lease Expiration | G11: Lease
A12: SCN-011 | B12: SMS | C12: (305) 555-6011 | D12: 3705 | E12: Is my work order still open? | F12: Work Orders | G12: Work order status
... A61: SCN-060 | B61: SMS | C61: (305) 555-6060 | D61: 3217 | E61: When does my tenant lease expire? | F61: Lease Expiration | G61: Lease
